[2025-07-17 13:38:32,701 - INFO - mlproject package initialized.]
[2025-07-17 13:39:46,448 - INFO - mlproject package initialized.]
[2025-07-17 13:41:08,985 - INFO - main - mlproject package initialized.]
[2025-07-18 19:38:44,272 - INFO - main - Welcome to Custom Logging]
[2025-07-18 19:38:44,272 - INFO - main - >>>>>>>>>>>>>>>>>> Data Ingestion Stage started <<<<<<<<<<<<<<<<<]
[2025-07-18 19:38:44,272 - ERROR - main - Argument file_path of type <class 'pathlib._local.PosixPath'> to <function read_yaml at 0x10132d120> does not match annotation type <class 'str'>]
Traceback (most recent call last):
  File "/Users/rahulsinghindata/AI-ML/ML_PROJECT_END_TO_END_17_07_2025/main.py", line 12, in <module>
    data_ingestion.main()
    ~~~~~~~~~~~~~~~~~~~^^
  File "/Users/rahulsinghindata/AI-ML/ML_PROJECT_END_TO_END_17_07_2025/src/mlproject/pipeline/stage_01_data_ingestion.py", line 13, in main
    config = ConfigurationManager()
  File "/Users/rahulsinghindata/AI-ML/ML_PROJECT_END_TO_END_17_07_2025/src/mlproject/config/configuration.py", line 12, in __init__
    self.config = read_yaml(config_file_path)
                  ~~~~~~~~~^^^^^^^^^^^^^^^^^^
  File "/Users/rahulsinghindata/AI-ML/ML_PROJECT_END_TO_END_17_07_2025/.venv/lib/python3.13/site-packages/ensure/main.py", line 870, in __call__
    raise EnsureError(msg.format(arg=arg, f=self.f, t=templ, valt=type(value)))
ensure.main.EnsureError: Argument file_path of type <class 'pathlib._local.PosixPath'> to <function read_yaml at 0x10132d120> does not match annotation type <class 'str'>
[2025-07-18 19:43:19,528 - INFO - main - Welcome to Custom Logging]
[2025-07-18 19:43:19,529 - INFO - main - >>>>>>>>>>>>>>>>>> Data Ingestion Stage started <<<<<<<<<<<<<<<<<]
[2025-07-18 19:43:19,529 - INFO - common - Successfully read YAML file at config/config.yaml]
[2025-07-18 19:43:19,530 - INFO - common - Successfully read YAML file at params.yaml]
[2025-07-18 19:43:19,530 - ERROR - main - Empty YAML structure in file: params.yaml]
Traceback (most recent call last):
  File "/Users/rahulsinghindata/AI-ML/ML_PROJECT_END_TO_END_17_07_2025/src/mlproject/utils/common.py", line 19, in read_yaml
    return ConfigBox(content)
  File "box/box.py", line 295, in box.box.Box.__init__
box.exceptions.BoxValueError: First argument must be mapping or iterable

During handling of the above exception, another exception occurred:

Traceback (most recent call last):
  File "/Users/rahulsinghindata/AI-ML/ML_PROJECT_END_TO_END_17_07_2025/main.py", line 12, in <module>
    data_ingestion.main()
    ~~~~~~~~~~~~~~~~~~~^^
  File "/Users/rahulsinghindata/AI-ML/ML_PROJECT_END_TO_END_17_07_2025/src/mlproject/pipeline/stage_01_data_ingestion.py", line 13, in main
    config = ConfigurationManager()
  File "/Users/rahulsinghindata/AI-ML/ML_PROJECT_END_TO_END_17_07_2025/src/mlproject/config/configuration.py", line 13, in __init__
    self.params = read_yaml(str(params_file_path))
                  ~~~~~~~~~^^^^^^^^^^^^^^^^^^^^^^^
  File "/Users/rahulsinghindata/AI-ML/ML_PROJECT_END_TO_END_17_07_2025/.venv/lib/python3.13/site-packages/ensure/main.py", line 872, in __call__
    return_val = self.f(*args, **kwargs)
  File "/Users/rahulsinghindata/AI-ML/ML_PROJECT_END_TO_END_17_07_2025/src/mlproject/utils/common.py", line 21, in read_yaml
    raise ValueError(f"Empty YAML structure in file: {file_path}")
ValueError: Empty YAML structure in file: params.yaml
[2025-07-18 19:43:51,521 - INFO - main - Welcome to Custom Logging]
[2025-07-18 19:43:51,521 - INFO - main - >>>>>>>>>>>>>>>>>> Data Ingestion Stage started <<<<<<<<<<<<<<<<<]
[2025-07-18 19:43:51,521 - INFO - common - Successfully read YAML file at config/config.yaml]
[2025-07-18 19:43:51,521 - INFO - common - Successfully read YAML file at params.yaml]
[2025-07-18 19:43:51,521 - INFO - common - Successfully read YAML file at schema.yaml]
[2025-07-18 19:43:51,521 - INFO - common - Directory created at: artifacts]
[2025-07-18 19:43:51,522 - ERROR - main - isinstance() arg 2 must be a type, a tuple of types, or a union]
Traceback (most recent call last):
  File "/Users/rahulsinghindata/AI-ML/ML_PROJECT_END_TO_END_17_07_2025/main.py", line 12, in <module>
    data_ingestion.main()
    ~~~~~~~~~~~~~~~~~~~^^
  File "/Users/rahulsinghindata/AI-ML/ML_PROJECT_END_TO_END_17_07_2025/src/mlproject/pipeline/stage_01_data_ingestion.py", line 13, in main
    config = ConfigurationManager()
  File "/Users/rahulsinghindata/AI-ML/ML_PROJECT_END_TO_END_17_07_2025/src/mlproject/config/configuration.py", line 16, in __init__
    create_directories([self.config.artifacts_root])
    ~~~~~~~~~~~~~~~~~~^^^^^^^^^^^^^^^^^^^^^^^^^^^^^^
  File "/Users/rahulsinghindata/AI-ML/ML_PROJECT_END_TO_END_17_07_2025/.venv/lib/python3.13/site-packages/ensure/main.py", line 873, in __call__
    if not isinstance(return_val, self.return_templ):
           ~~~~~~~~~~^^^^^^^^^^^^^^^^^^^^^^^^^^^^^^^
TypeError: isinstance() arg 2 must be a type, a tuple of types, or a union
[2025-07-18 19:49:36,549 - INFO - main - Welcome to Custom Logging]
[2025-07-18 19:49:36,549 - INFO - main - >>>>>>>>>>>>>>>>>> Data Ingestion Stage started <<<<<<<<<<<<<<<<<]
[2025-07-18 19:49:36,549 - INFO - common - Successfully read YAML file at config/config.yaml]
[2025-07-18 19:49:36,550 - INFO - common - Successfully read YAML file at params.yaml]
[2025-07-18 19:49:36,550 - INFO - common - Successfully read YAML file at schema.yaml]
[2025-07-18 19:49:36,550 - ERROR - main - isinstance() argument 2 cannot be a parameterized generic]
Traceback (most recent call last):
  File "/Users/rahulsinghindata/AI-ML/ML_PROJECT_END_TO_END_17_07_2025/main.py", line 12, in <module>
    data_ingestion.main()
    ~~~~~~~~~~~~~~~~~~~^^
  File "/Users/rahulsinghindata/AI-ML/ML_PROJECT_END_TO_END_17_07_2025/src/mlproject/pipeline/stage_01_data_ingestion.py", line 13, in main
    config = ConfigurationManager()
  File "/Users/rahulsinghindata/AI-ML/ML_PROJECT_END_TO_END_17_07_2025/src/mlproject/config/configuration.py", line 16, in __init__
    create_directories([self.config.artifacts_root])
    ~~~~~~~~~~~~~~~~~~^^^^^^^^^^^^^^^^^^^^^^^^^^^^^^
  File "/Users/rahulsinghindata/AI-ML/ML_PROJECT_END_TO_END_17_07_2025/.venv/lib/python3.13/site-packages/ensure/main.py", line 868, in __call__
    if not isinstance(value, templ):
           ~~~~~~~~~~^^^^^^^^^^^^^^
TypeError: isinstance() argument 2 cannot be a parameterized generic
[2025-07-18 19:52:39,494 - INFO - main - Welcome to Custom Logging]
[2025-07-18 19:52:39,494 - INFO - main - >>>>>>>>>>>>>>>>>> Data Ingestion Stage started <<<<<<<<<<<<<<<<<]
[2025-07-18 19:52:39,495 - INFO - common - Successfully read YAML file at config/config.yaml]
[2025-07-18 19:52:39,495 - INFO - common - Successfully read YAML file at params.yaml]
[2025-07-18 19:52:39,495 - INFO - common - Successfully read YAML file at schema.yaml]
[2025-07-18 19:52:39,495 - ERROR - main - Subscripted generics cannot be used with class and instance checks]
Traceback (most recent call last):
  File "/Users/rahulsinghindata/AI-ML/ML_PROJECT_END_TO_END_17_07_2025/main.py", line 12, in <module>
    data_ingestion.main()
    ~~~~~~~~~~~~~~~~~~~^^
  File "/Users/rahulsinghindata/AI-ML/ML_PROJECT_END_TO_END_17_07_2025/src/mlproject/pipeline/stage_01_data_ingestion.py", line 13, in main
    config = ConfigurationManager()
  File "/Users/rahulsinghindata/AI-ML/ML_PROJECT_END_TO_END_17_07_2025/src/mlproject/config/configuration.py", line 16, in __init__
    create_directories([self.config.artifacts_root])
    ~~~~~~~~~~~~~~~~~~^^^^^^^^^^^^^^^^^^^^^^^^^^^^^^
  File "/Users/rahulsinghindata/AI-ML/ML_PROJECT_END_TO_END_17_07_2025/.venv/lib/python3.13/site-packages/ensure/main.py", line 868, in __call__
    if not isinstance(value, templ):
           ~~~~~~~~~~^^^^^^^^^^^^^^
  File "/Library/Frameworks/Python.framework/Versions/3.13/lib/python3.13/typing.py", line 1375, in __instancecheck__
    return self.__subclasscheck__(type(obj))
           ~~~~~~~~~~~~~~~~~~~~~~^^^^^^^^^^^
  File "/Library/Frameworks/Python.framework/Versions/3.13/lib/python3.13/typing.py", line 1378, in __subclasscheck__
    raise TypeError("Subscripted generics cannot be used with"
                    " class and instance checks")
TypeError: Subscripted generics cannot be used with class and instance checks
[2025-07-18 19:54:44,031 - INFO - main - Welcome to Custom Logging]
[2025-07-18 19:54:44,031 - INFO - main - >>>>>>>>>>>>>>>>>> Data Ingestion Stage started <<<<<<<<<<<<<<<<<]
[2025-07-18 19:54:44,031 - INFO - common - Successfully read YAML file at config/config.yaml]
[2025-07-18 19:54:44,032 - INFO - common - Successfully read YAML file at params.yaml]
[2025-07-18 19:54:44,032 - INFO - common - Successfully read YAML file at schema.yaml]
[2025-07-18 19:54:44,032 - INFO - common - Directory created at: artifacts]
[2025-07-18 19:54:44,032 - ERROR - main - isinstance() arg 2 must be a type, a tuple of types, or a union]
Traceback (most recent call last):
  File "/Users/rahulsinghindata/AI-ML/ML_PROJECT_END_TO_END_17_07_2025/main.py", line 12, in <module>
    data_ingestion.main()
    ~~~~~~~~~~~~~~~~~~~^^
  File "/Users/rahulsinghindata/AI-ML/ML_PROJECT_END_TO_END_17_07_2025/src/mlproject/pipeline/stage_01_data_ingestion.py", line 13, in main
    config = ConfigurationManager()
  File "/Users/rahulsinghindata/AI-ML/ML_PROJECT_END_TO_END_17_07_2025/src/mlproject/config/configuration.py", line 16, in __init__
    create_directories([self.config.artifacts_root])
    ~~~~~~~~~~~~~~~~~~^^^^^^^^^^^^^^^^^^^^^^^^^^^^^^
  File "/Users/rahulsinghindata/AI-ML/ML_PROJECT_END_TO_END_17_07_2025/.venv/lib/python3.13/site-packages/ensure/main.py", line 873, in __call__
    if not isinstance(return_val, self.return_templ):
           ~~~~~~~~~~^^^^^^^^^^^^^^^^^^^^^^^^^^^^^^^
TypeError: isinstance() arg 2 must be a type, a tuple of types, or a union
[2025-07-18 19:55:50,691 - INFO - main - Welcome to Custom Logging]
[2025-07-18 19:55:50,691 - INFO - main - >>>>>>>>>>>>>>>>>> Data Ingestion Stage started <<<<<<<<<<<<<<<<<]
[2025-07-18 19:55:50,691 - INFO - common - Successfully read YAML file at config/config.yaml]
[2025-07-18 19:55:50,692 - INFO - common - Successfully read YAML file at params.yaml]
[2025-07-18 19:55:50,692 - INFO - common - Successfully read YAML file at schema.yaml]
[2025-07-18 19:55:50,692 - INFO - common - Directory created at: artifacts]
[2025-07-18 19:55:50,692 - ERROR - main - isinstance() arg 2 must be a type, a tuple of types, or a union]
Traceback (most recent call last):
  File "/Users/rahulsinghindata/AI-ML/ML_PROJECT_END_TO_END_17_07_2025/main.py", line 12, in <module>
    data_ingestion.main()
    ~~~~~~~~~~~~~~~~~~~^^
  File "/Users/rahulsinghindata/AI-ML/ML_PROJECT_END_TO_END_17_07_2025/src/mlproject/pipeline/stage_01_data_ingestion.py", line 13, in main
    config = ConfigurationManager()
  File "/Users/rahulsinghindata/AI-ML/ML_PROJECT_END_TO_END_17_07_2025/src/mlproject/config/configuration.py", line 16, in __init__
    create_directories([self.config.artifacts_root])
    ~~~~~~~~~~~~~~~~~~^^^^^^^^^^^^^^^^^^^^^^^^^^^^^^
  File "/Users/rahulsinghindata/AI-ML/ML_PROJECT_END_TO_END_17_07_2025/.venv/lib/python3.13/site-packages/ensure/main.py", line 873, in __call__
    if not isinstance(return_val, self.return_templ):
           ~~~~~~~~~~^^^^^^^^^^^^^^^^^^^^^^^^^^^^^^^
TypeError: isinstance() arg 2 must be a type, a tuple of types, or a union
[2025-07-18 19:56:07,122 - INFO - main - Welcome to Custom Logging]
[2025-07-18 19:56:07,122 - INFO - main - >>>>>>>>>>>>>>>>>> Data Ingestion Stage started <<<<<<<<<<<<<<<<<]
[2025-07-18 19:56:07,122 - INFO - common - Successfully read YAML file at config/config.yaml]
[2025-07-18 19:56:07,122 - INFO - common - Successfully read YAML file at params.yaml]
[2025-07-18 19:56:07,122 - INFO - common - Successfully read YAML file at schema.yaml]
[2025-07-18 19:56:07,122 - INFO - common - Directory created at: artifacts]
[2025-07-18 19:56:07,122 - INFO - common - Directory created at: artifacts/data_ingestion]
[2025-07-18 19:56:07,122 - INFO - common - Directory created at: artifacts/data_ingestion]
[2025-07-18 19:56:07,123 - ERROR - main - type object 'Request' has no attribute 'urlretrieve']
Traceback (most recent call last):
  File "/Users/rahulsinghindata/AI-ML/ML_PROJECT_END_TO_END_17_07_2025/main.py", line 12, in <module>
    data_ingestion.main()
    ~~~~~~~~~~~~~~~~~~~^^
  File "/Users/rahulsinghindata/AI-ML/ML_PROJECT_END_TO_END_17_07_2025/src/mlproject/pipeline/stage_01_data_ingestion.py", line 16, in main
    data_ingestion.download_file()
    ~~~~~~~~~~~~~~~~~~~~~~~~~~~~^^
  File "/Users/rahulsinghindata/AI-ML/ML_PROJECT_END_TO_END_17_07_2025/src/mlproject/components/data_ingestion.py", line 18, in download_file
    filename, headers = Request.urlretrieve(
                        ^^^^^^^^^^^^^^^^^^^
AttributeError: type object 'Request' has no attribute 'urlretrieve'
[2025-07-18 19:59:25,274 - INFO - main - Welcome to Custom Logging]
[2025-07-18 19:59:25,274 - INFO - main - >>>>>>>>>>>>>>>>>> Data Ingestion Stage started <<<<<<<<<<<<<<<<<]
[2025-07-18 19:59:25,274 - INFO - common - Successfully read YAML file at config/config.yaml]
[2025-07-18 19:59:25,274 - INFO - common - Successfully read YAML file at params.yaml]
[2025-07-18 19:59:25,274 - INFO - common - Successfully read YAML file at schema.yaml]
[2025-07-18 19:59:25,274 - INFO - common - Directory created at: artifacts]
[2025-07-18 19:59:25,274 - INFO - common - Directory created at: artifacts/data_ingestion]
[2025-07-18 19:59:25,274 - INFO - common - Directory created at: artifacts/data_ingestion]
[2025-07-18 19:59:25,393 - ERROR - main - <urlopen error [SSL: CERTIFICATE_VERIFY_FAILED] certificate verify failed: unable to get local issuer certificate (_ssl.c:1028)>]
Traceback (most recent call last):
  File "/Library/Frameworks/Python.framework/Versions/3.13/lib/python3.13/urllib/request.py", line 1319, in do_open
    h.request(req.get_method(), req.selector, req.data, headers,
    ~~~~~~~~~^^^^^^^^^^^^^^^^^^^^^^^^^^^^^^^^^^^^^^^^^^^^^^^^^^^
              encode_chunked=req.has_header('Transfer-encoding'))
              ^^^^^^^^^^^^^^^^^^^^^^^^^^^^^^^^^^^^^^^^^^^^^^^^^^^
  File "/Library/Frameworks/Python.framework/Versions/3.13/lib/python3.13/http/client.py", line 1338, in request
    self._send_request(method, url, body, headers, encode_chunked)
    ~~~~~~~~~~~~~~~~~~^^^^^^^^^^^^^^^^^^^^^^^^^^^^^^^^^^^^^^^^^^^^
  File "/Library/Frameworks/Python.framework/Versions/3.13/lib/python3.13/http/client.py", line 1384, in _send_request
    self.endheaders(body, encode_chunked=encode_chunked)
    ~~~~~~~~~~~~~~~^^^^^^^^^^^^^^^^^^^^^^^^^^^^^^^^^^^^^
  File "/Library/Frameworks/Python.framework/Versions/3.13/lib/python3.13/http/client.py", line 1333, in endheaders
    self._send_output(message_body, encode_chunked=encode_chunked)
    ~~~~~~~~~~~~~~~~~^^^^^^^^^^^^^^^^^^^^^^^^^^^^^^^^^^^^^^^^^^^^^
  File "/Library/Frameworks/Python.framework/Versions/3.13/lib/python3.13/http/client.py", line 1093, in _send_output
    self.send(msg)
    ~~~~~~~~~^^^^^
  File "/Library/Frameworks/Python.framework/Versions/3.13/lib/python3.13/http/client.py", line 1037, in send
    self.connect()
    ~~~~~~~~~~~~^^
  File "/Library/Frameworks/Python.framework/Versions/3.13/lib/python3.13/http/client.py", line 1479, in connect
    self.sock = self._context.wrap_socket(self.sock,
                ~~~~~~~~~~~~~~~~~~~~~~~~~^^^^^^^^^^^
                                          server_hostname=server_hostname)
                                          ^^^^^^^^^^^^^^^^^^^^^^^^^^^^^^^^
  File "/Library/Frameworks/Python.framework/Versions/3.13/lib/python3.13/ssl.py", line 455, in wrap_socket
    return self.sslsocket_class._create(
           ~~~~~~~~~~~~~~~~~~~~~~~~~~~~^
        sock=sock,
        ^^^^^^^^^^
    ...<5 lines>...
        session=session
        ^^^^^^^^^^^^^^^
    )
    ^
  File "/Library/Frameworks/Python.framework/Versions/3.13/lib/python3.13/ssl.py", line 1076, in _create
    self.do_handshake()
    ~~~~~~~~~~~~~~~~~^^
  File "/Library/Frameworks/Python.framework/Versions/3.13/lib/python3.13/ssl.py", line 1372, in do_handshake
    self._sslobj.do_handshake()
    ~~~~~~~~~~~~~~~~~~~~~~~~~^^
ssl.SSLCertVerificationError: [SSL: CERTIFICATE_VERIFY_FAILED] certificate verify failed: unable to get local issuer certificate (_ssl.c:1028)

During handling of the above exception, another exception occurred:

Traceback (most recent call last):
  File "/Users/rahulsinghindata/AI-ML/ML_PROJECT_END_TO_END_17_07_2025/main.py", line 12, in <module>
    data_ingestion.main()
    ~~~~~~~~~~~~~~~~~~~^^
  File "/Users/rahulsinghindata/AI-ML/ML_PROJECT_END_TO_END_17_07_2025/src/mlproject/pipeline/stage_01_data_ingestion.py", line 16, in main
    data_ingestion.download_file()
    ~~~~~~~~~~~~~~~~~~~~~~~~~~~~^^
  File "/Users/rahulsinghindata/AI-ML/ML_PROJECT_END_TO_END_17_07_2025/src/mlproject/components/data_ingestion.py", line 18, in download_file
    filename, headers = urlretrieve(
                        ~~~~~~~~~~~^
        url = self.config.source_url,
        ^^^^^^^^^^^^^^^^^^^^^^^^^^^^^
        filename = self.config.local_data_file
        ^^^^^^^^^^^^^^^^^^^^^^^^^^^^^^^^^^^^^^
    )
    ^
  File "/Library/Frameworks/Python.framework/Versions/3.13/lib/python3.13/urllib/request.py", line 214, in urlretrieve
    with contextlib.closing(urlopen(url, data)) as fp:
                            ~~~~~~~^^^^^^^^^^^
  File "/Library/Frameworks/Python.framework/Versions/3.13/lib/python3.13/urllib/request.py", line 189, in urlopen
    return opener.open(url, data, timeout)
           ~~~~~~~~~~~^^^^^^^^^^^^^^^^^^^^
  File "/Library/Frameworks/Python.framework/Versions/3.13/lib/python3.13/urllib/request.py", line 489, in open
    response = self._open(req, data)
  File "/Library/Frameworks/Python.framework/Versions/3.13/lib/python3.13/urllib/request.py", line 506, in _open
    result = self._call_chain(self.handle_open, protocol, protocol +
                              '_open', req)
  File "/Library/Frameworks/Python.framework/Versions/3.13/lib/python3.13/urllib/request.py", line 466, in _call_chain
    result = func(*args)
  File "/Library/Frameworks/Python.framework/Versions/3.13/lib/python3.13/urllib/request.py", line 1367, in https_open
    return self.do_open(http.client.HTTPSConnection, req,
           ~~~~~~~~~~~~^^^^^^^^^^^^^^^^^^^^^^^^^^^^^^^^^^
                        context=self._context)
                        ^^^^^^^^^^^^^^^^^^^^^^
  File "/Library/Frameworks/Python.framework/Versions/3.13/lib/python3.13/urllib/request.py", line 1322, in do_open
    raise URLError(err)
urllib.error.URLError: <urlopen error [SSL: CERTIFICATE_VERIFY_FAILED] certificate verify failed: unable to get local issuer certificate (_ssl.c:1028)>
[2025-07-18 20:02:36,636 - INFO - main - Welcome to Custom Logging]
[2025-07-18 20:02:36,636 - INFO - main - >>>>>>>>>>>>>>>>>> Data Ingestion Stage started <<<<<<<<<<<<<<<<<]
[2025-07-18 20:02:36,637 - INFO - common - Successfully read YAML file at config/config.yaml]
[2025-07-18 20:02:36,637 - INFO - common - Successfully read YAML file at params.yaml]
[2025-07-18 20:02:36,638 - INFO - common - Successfully read YAML file at schema.yaml]
[2025-07-18 20:02:36,638 - INFO - common - Directory created at: artifacts]
[2025-07-18 20:02:36,638 - INFO - common - Directory created at: artifacts/data_ingestion]
[2025-07-18 20:02:36,638 - INFO - common - Directory created at: artifacts/data_ingestion]
[2025-07-18 20:02:37,647 - INFO - data_ingestion - Downloaded file: artifacts/data_ingestion/data.zip]
[2025-07-18 20:02:37,652 - INFO - data_ingestion - Extracted files to artifacts/data_ingestion]
[2025-07-18 20:02:37,652 - INFO - main - >>>>>>>>>>>>>>>>>> Data Ingestion Stage completed <<<<<<<<<<<<<<<<<]
[2025-07-18 20:25:33,975 - INFO - main - Welcome to Custom Logging]
[2025-07-18 20:25:33,975 - INFO - main - >>>>>>>>>>>>>>>>>> Data Ingestion Stage started <<<<<<<<<<<<<<<<<]
[2025-07-18 20:25:33,976 - INFO - common - Successfully read YAML file at config/config.yaml]
[2025-07-18 20:25:33,977 - INFO - common - Successfully read YAML file at params.yaml]
[2025-07-18 20:25:33,977 - INFO - common - Successfully read YAML file at schema.yaml]
[2025-07-18 20:25:33,977 - INFO - common - Directory created at: artifacts]
[2025-07-18 20:25:33,977 - INFO - common - Directory created at: artifacts/data_ingestion]
[2025-07-18 20:25:33,977 - INFO - common - Directory created at: artifacts/data_ingestion]
[2025-07-18 20:25:34,704 - INFO - data_ingestion - Downloaded file: artifacts/data_ingestion/data.zip]
[2025-07-18 20:25:34,707 - INFO - data_ingestion - Extracted files to artifacts/data_ingestion]
[2025-07-18 20:25:34,707 - INFO - main - >>>>>>>>>>>>>>>>>> Data Ingestion Stage completed <<<<<<<<<<<<<<<<<]
[2025-07-19 01:58:04,651 - INFO - common - Successfully read YAML file at config/config.yaml]
[2025-07-19 01:58:04,653 - INFO - common - Successfully read YAML file at params.yaml]
[2025-07-19 01:58:04,655 - INFO - common - Successfully read YAML file at schema.yaml]
[2025-07-19 01:58:04,655 - INFO - common - Directory created at: artifacts]
[2025-07-19 02:25:27,840 - INFO - main - Welcome to Custom Logging]
[2025-07-19 02:25:27,840 - INFO - main - >>>>>>>>>>>>>>>>>> Data Ingestion Stage started <<<<<<<<<<<<<<<<<]
[2025-07-19 02:25:27,841 - INFO - common - Successfully read YAML file at config/config.yaml]
[2025-07-19 02:25:27,841 - INFO - common - Successfully read YAML file at params.yaml]
[2025-07-19 02:25:27,841 - INFO - common - Successfully read YAML file at schema.yaml]
[2025-07-19 02:25:27,842 - INFO - common - Directory created at: artifacts]
[2025-07-19 02:25:27,842 - INFO - common - Directory created at: artifacts/data_ingestion]
[2025-07-19 02:25:27,842 - INFO - common - Directory created at: artifacts/data_ingestion]
[2025-07-19 02:25:27,842 - INFO - data_ingestion - File already exists at artifacts/data_ingestion/data.zip]
[2025-07-19 02:25:27,843 - INFO - data_ingestion - Extracted files to artifacts/data_ingestion]
[2025-07-19 02:25:27,843 - INFO - main - >>>>>>>>>>>>>>>>>> Data Ingestion Stage completed <<<<<<<<<<<<<<<<<]
[2025-07-19 02:25:27,843 - INFO - main - >>>>>>>>>>>>>>>>>> Data Validation Stage started <<<<<<<<<<<<<<<<<]
[2025-07-19 02:25:27,843 - INFO - common - Successfully read YAML file at config/config.yaml]
[2025-07-19 02:25:27,843 - INFO - common - Successfully read YAML file at params.yaml]
[2025-07-19 02:25:27,844 - INFO - common - Successfully read YAML file at schema.yaml]
[2025-07-19 02:25:27,844 - INFO - common - Directory created at: artifacts]
[2025-07-19 02:25:27,844 - ERROR - main - "'ConfigBox' object has no attribute 'data_validation'"]
Traceback (most recent call last):
  File "box/box.py", line 594, in box.box.Box.__getitem__
KeyError: 'data_validation'

The above exception was the direct cause of the following exception:

Traceback (most recent call last):
  File "box/box.py", line 633, in box.box.Box.__getattr__
  File "box/box.py", line 621, in box.box.Box.__getitem__
box.exceptions.BoxKeyError: "'data_validation'"

During handling of the above exception, another exception occurred:

Traceback (most recent call last):
  File "box/box.py", line 635, in box.box.Box.__getattr__
AttributeError: 'ConfigBox' object has no attribute 'data_validation'

The above exception was the direct cause of the following exception:

Traceback (most recent call last):
  File "box/config_box.py", line 29, in box.config_box.ConfigBox.__getattr__
  File "box/box.py", line 649, in box.box.Box.__getattr__
box.exceptions.BoxKeyError: "'ConfigBox' object has no attribute 'data_validation'"

During handling of the above exception, another exception occurred:

Traceback (most recent call last):
  File "box/box.py", line 594, in box.box.Box.__getitem__
KeyError: 'data_validation'

The above exception was the direct cause of the following exception:

Traceback (most recent call last):
  File "box/box.py", line 633, in box.box.Box.__getattr__
  File "box/box.py", line 621, in box.box.Box.__getitem__
box.exceptions.BoxKeyError: "'data_validation'"

During handling of the above exception, another exception occurred:

Traceback (most recent call last):
  File "box/box.py", line 635, in box.box.Box.__getattr__
AttributeError: 'ConfigBox' object has no attribute 'data_validation'

The above exception was the direct cause of the following exception:

Traceback (most recent call last):
  File "/Users/rahulsinghindata/AI-ML/ML_PROJECT_END_TO_END_17_07_2025/main.py", line 24, in <module>
    data_validation.main()
    ~~~~~~~~~~~~~~~~~~~~^^
  File "/Users/rahulsinghindata/AI-ML/ML_PROJECT_END_TO_END_17_07_2025/src/mlproject/pipeline/stage_02_data_validation.py", line 14, in main
    data_validation_config = config.get_data_validation_config()
  File "/Users/rahulsinghindata/AI-ML/ML_PROJECT_END_TO_END_17_07_2025/src/mlproject/config/configuration.py", line 38, in get_data_validation_config
    schema = self.schema.data_validation
             ^^^^^^^^^^^^^^^^^^^^^^^^^^^
  File "box/config_box.py", line 31, in box.config_box.ConfigBox.__getattr__
  File "box/box.py", line 649, in box.box.Box.__getattr__
box.exceptions.BoxKeyError: "'ConfigBox' object has no attribute 'data_validation'"
[2025-07-19 02:29:10,978 - INFO - main - Welcome to Custom Logging]
[2025-07-19 02:29:10,978 - INFO - main - >>>>>>>>>>>>>>>>>> Data Ingestion Stage started <<<<<<<<<<<<<<<<<]
[2025-07-19 02:29:10,979 - INFO - common - Successfully read YAML file at config/config.yaml]
[2025-07-19 02:29:10,979 - INFO - common - Successfully read YAML file at params.yaml]
[2025-07-19 02:29:10,980 - INFO - common - Successfully read YAML file at schema.yaml]
[2025-07-19 02:29:10,980 - INFO - common - Directory created at: artifacts]
[2025-07-19 02:29:10,980 - INFO - common - Directory created at: artifacts/data_ingestion]
[2025-07-19 02:29:10,980 - INFO - common - Directory created at: artifacts/data_ingestion]
[2025-07-19 02:29:10,980 - INFO - data_ingestion - File already exists at artifacts/data_ingestion/data.zip]
[2025-07-19 02:29:10,980 - INFO - data_ingestion - Extracted files to artifacts/data_ingestion]
[2025-07-19 02:29:10,980 - INFO - main - >>>>>>>>>>>>>>>>>> Data Ingestion Stage completed <<<<<<<<<<<<<<<<<]
[2025-07-19 02:29:10,980 - INFO - main - >>>>>>>>>>>>>>>>>> Data Validation Stage started <<<<<<<<<<<<<<<<<]
[2025-07-19 02:29:10,981 - INFO - common - Successfully read YAML file at config/config.yaml]
[2025-07-19 02:29:10,981 - INFO - common - Successfully read YAML file at params.yaml]
[2025-07-19 02:29:10,981 - INFO - common - Successfully read YAML file at schema.yaml]
[2025-07-19 02:29:10,981 - INFO - common - Directory created at: artifacts]
[2025-07-19 02:29:10,982 - INFO - common - Directory created at: artifacts/data_validation]
[2025-07-19 02:29:10,982 - ERROR - main - "'ConfigBox' object has no attribute 'source_url'"]
Traceback (most recent call last):
  File "box/box.py", line 594, in box.box.Box.__getitem__
KeyError: 'source_url'

The above exception was the direct cause of the following exception:

Traceback (most recent call last):
  File "box/box.py", line 633, in box.box.Box.__getattr__
  File "box/box.py", line 621, in box.box.Box.__getitem__
box.exceptions.BoxKeyError: "'source_url'"

During handling of the above exception, another exception occurred:

Traceback (most recent call last):
  File "box/box.py", line 635, in box.box.Box.__getattr__
AttributeError: 'ConfigBox' object has no attribute 'source_url'

The above exception was the direct cause of the following exception:

Traceback (most recent call last):
  File "box/config_box.py", line 29, in box.config_box.ConfigBox.__getattr__
  File "box/box.py", line 649, in box.box.Box.__getattr__
box.exceptions.BoxKeyError: "'ConfigBox' object has no attribute 'source_url'"

During handling of the above exception, another exception occurred:

Traceback (most recent call last):
  File "box/box.py", line 594, in box.box.Box.__getitem__
KeyError: 'source_url'

The above exception was the direct cause of the following exception:

Traceback (most recent call last):
  File "box/box.py", line 633, in box.box.Box.__getattr__
  File "box/box.py", line 621, in box.box.Box.__getitem__
box.exceptions.BoxKeyError: "'source_url'"

During handling of the above exception, another exception occurred:

Traceback (most recent call last):
  File "box/box.py", line 635, in box.box.Box.__getattr__
AttributeError: 'ConfigBox' object has no attribute 'source_url'

The above exception was the direct cause of the following exception:

Traceback (most recent call last):
  File "/Users/rahulsinghindata/AI-ML/ML_PROJECT_END_TO_END_17_07_2025/main.py", line 24, in <module>
    data_validation.main()
    ~~~~~~~~~~~~~~~~~~~~^^
  File "/Users/rahulsinghindata/AI-ML/ML_PROJECT_END_TO_END_17_07_2025/src/mlproject/pipeline/stage_02_data_validation.py", line 14, in main
    data_validation_config = config.get_data_validation_config()
  File "/Users/rahulsinghindata/AI-ML/ML_PROJECT_END_TO_END_17_07_2025/src/mlproject/config/configuration.py", line 44, in get_data_validation_config
    source_url=config.source_url,
               ^^^^^^^^^^^^^^^^^
  File "box/config_box.py", line 31, in box.config_box.ConfigBox.__getattr__
  File "box/box.py", line 649, in box.box.Box.__getattr__
box.exceptions.BoxKeyError: "'ConfigBox' object has no attribute 'source_url'"
[2025-07-19 12:34:41,262 - INFO - main - Welcome to Custom Logging]
[2025-07-19 12:34:41,262 - INFO - main - >>>>>>>>>>>>>>>>>> Data Ingestion Stage started <<<<<<<<<<<<<<<<<]
[2025-07-19 12:34:41,263 - INFO - common - Successfully read YAML file at config/config.yaml]
[2025-07-19 12:34:41,263 - INFO - common - Successfully read YAML file at params.yaml]
[2025-07-19 12:34:41,264 - INFO - common - Successfully read YAML file at schema.yaml]
[2025-07-19 12:34:41,264 - INFO - common - Directory created at: artifacts]
[2025-07-19 12:34:41,264 - INFO - common - Directory created at: artifacts/data_ingestion]
[2025-07-19 12:34:41,264 - INFO - common - Directory created at: artifacts/data_ingestion]
[2025-07-19 12:34:41,264 - INFO - data_ingestion - File already exists at artifacts/data_ingestion/data.zip]
[2025-07-19 12:34:41,265 - INFO - data_ingestion - Extracted files to artifacts/data_ingestion]
[2025-07-19 12:34:41,265 - INFO - main - >>>>>>>>>>>>>>>>>> Data Ingestion Stage completed <<<<<<<<<<<<<<<<<]
[2025-07-19 12:34:41,265 - INFO - main - >>>>>>>>>>>>>>>>>> Data Validation Stage started <<<<<<<<<<<<<<<<<]
[2025-07-19 12:34:41,265 - INFO - common - Successfully read YAML file at config/config.yaml]
[2025-07-19 12:34:41,265 - INFO - common - Successfully read YAML file at params.yaml]
[2025-07-19 12:34:41,266 - INFO - common - Successfully read YAML file at schema.yaml]
[2025-07-19 12:34:41,266 - INFO - common - Directory created at: artifacts]
[2025-07-19 12:34:41,266 - INFO - common - Directory created at: artifacts/data_validation]
[2025-07-19 12:34:41,266 - ERROR - main - "'ConfigBox' object has no attribute 'source_url'"]
Traceback (most recent call last):
  File "box/box.py", line 594, in box.box.Box.__getitem__
KeyError: 'source_url'

The above exception was the direct cause of the following exception:

Traceback (most recent call last):
  File "box/box.py", line 633, in box.box.Box.__getattr__
  File "box/box.py", line 621, in box.box.Box.__getitem__
box.exceptions.BoxKeyError: "'source_url'"

During handling of the above exception, another exception occurred:

Traceback (most recent call last):
  File "box/box.py", line 635, in box.box.Box.__getattr__
AttributeError: 'ConfigBox' object has no attribute 'source_url'

The above exception was the direct cause of the following exception:

Traceback (most recent call last):
  File "box/config_box.py", line 29, in box.config_box.ConfigBox.__getattr__
  File "box/box.py", line 649, in box.box.Box.__getattr__
box.exceptions.BoxKeyError: "'ConfigBox' object has no attribute 'source_url'"

During handling of the above exception, another exception occurred:

Traceback (most recent call last):
  File "box/box.py", line 594, in box.box.Box.__getitem__
KeyError: 'source_url'

The above exception was the direct cause of the following exception:

Traceback (most recent call last):
  File "box/box.py", line 633, in box.box.Box.__getattr__
  File "box/box.py", line 621, in box.box.Box.__getitem__
box.exceptions.BoxKeyError: "'source_url'"

During handling of the above exception, another exception occurred:

Traceback (most recent call last):
  File "box/box.py", line 635, in box.box.Box.__getattr__
AttributeError: 'ConfigBox' object has no attribute 'source_url'

The above exception was the direct cause of the following exception:

Traceback (most recent call last):
  File "/Users/rahulsinghindata/AI-ML/ML_PROJECT_END_TO_END_17_07_2025/main.py", line 24, in <module>
    data_validation.main()
    ~~~~~~~~~~~~~~~~~~~~^^
  File "/Users/rahulsinghindata/AI-ML/ML_PROJECT_END_TO_END_17_07_2025/src/mlproject/pipeline/stage_02_data_validation.py", line 14, in main
    data_validation_config = config.get_data_validation_config()
  File "/Users/rahulsinghindata/AI-ML/ML_PROJECT_END_TO_END_17_07_2025/src/mlproject/config/configuration.py", line 44, in get_data_validation_config
    source_url=config.source_url,
               ^^^^^^^^^^^^^^^^^
  File "box/config_box.py", line 31, in box.config_box.ConfigBox.__getattr__
  File "box/box.py", line 649, in box.box.Box.__getattr__
box.exceptions.BoxKeyError: "'ConfigBox' object has no attribute 'source_url'"
[2025-07-19 12:51:05,997 - INFO - main - Welcome to Custom Logging]
[2025-07-19 12:51:05,998 - INFO - main - >>>>>>>>>>>>>>>>>> Data Ingestion Stage started <<<<<<<<<<<<<<<<<]
[2025-07-19 12:51:05,998 - INFO - common - Successfully read YAML file at config/config.yaml]
[2025-07-19 12:51:05,999 - INFO - common - Successfully read YAML file at params.yaml]
[2025-07-19 12:51:06,000 - INFO - common - Successfully read YAML file at schema.yaml]
[2025-07-19 12:51:06,000 - INFO - common - Directory created at: artifacts]
[2025-07-19 12:51:06,000 - INFO - common - Directory created at: artifacts/data_ingestion]
[2025-07-19 12:51:06,000 - INFO - common - Directory created at: artifacts/data_ingestion]
[2025-07-19 12:51:06,000 - INFO - data_ingestion - File already exists at artifacts/data_ingestion/data.zip]
[2025-07-19 12:51:06,001 - INFO - data_ingestion - Extracted files to artifacts/data_ingestion]
[2025-07-19 12:51:06,001 - INFO - main - >>>>>>>>>>>>>>>>>> Data Ingestion Stage completed <<<<<<<<<<<<<<<<<]
[2025-07-19 12:51:06,001 - INFO - main - >>>>>>>>>>>>>>>>>> Data Validation Stage started <<<<<<<<<<<<<<<<<]
[2025-07-19 12:51:06,001 - INFO - common - Successfully read YAML file at config/config.yaml]
[2025-07-19 12:51:06,001 - INFO - common - Successfully read YAML file at params.yaml]
[2025-07-19 12:51:06,002 - INFO - common - Successfully read YAML file at schema.yaml]
[2025-07-19 12:51:06,002 - INFO - common - Directory created at: artifacts]
[2025-07-19 12:51:06,002 - INFO - common - Directory created at: artifacts/data_validation]
[2025-07-19 12:51:06,002 - ERROR - main - DataValidationConfig.__init__() got an unexpected keyword argument 'STATUS_FILE']
Traceback (most recent call last):
  File "/Users/rahulsinghindata/AI-ML/ML_PROJECT_END_TO_END_17_07_2025/main.py", line 24, in <module>
    data_validation.main()
    ~~~~~~~~~~~~~~~~~~~~^^
  File "/Users/rahulsinghindata/AI-ML/ML_PROJECT_END_TO_END_17_07_2025/src/mlproject/pipeline/stage_02_data_validation.py", line 14, in main
    data_validation_config = config.get_data_validation_config()
  File "/Users/rahulsinghindata/AI-ML/ML_PROJECT_END_TO_END_17_07_2025/src/mlproject/config/configuration.py", line 42, in get_data_validation_config
    data_validation_config = DataValidationConfig(
        root_dir=config.root_dir,
    ...<2 lines>...
        all_schema=schema
    )
TypeError: DataValidationConfig.__init__() got an unexpected keyword argument 'STATUS_FILE'
[2025-07-19 12:54:40,977 - INFO - main - Welcome to Custom Logging]
[2025-07-19 12:54:40,977 - INFO - main - >>>>>>>>>>>>>>>>>> Data Ingestion Stage started <<<<<<<<<<<<<<<<<]
[2025-07-19 12:54:40,977 - INFO - common - Successfully read YAML file at config/config.yaml]
[2025-07-19 12:54:40,978 - INFO - common - Successfully read YAML file at params.yaml]
[2025-07-19 12:54:40,979 - INFO - common - Successfully read YAML file at schema.yaml]
[2025-07-19 12:54:40,979 - INFO - common - Directory created at: artifacts]
[2025-07-19 12:54:40,979 - INFO - common - Directory created at: artifacts/data_ingestion]
[2025-07-19 12:54:40,979 - INFO - common - Directory created at: artifacts/data_ingestion]
[2025-07-19 12:54:40,979 - INFO - data_ingestion - File already exists at artifacts/data_ingestion/data.zip]
[2025-07-19 12:54:40,980 - INFO - data_ingestion - Extracted files to artifacts/data_ingestion]
[2025-07-19 12:54:40,980 - INFO - main - >>>>>>>>>>>>>>>>>> Data Ingestion Stage completed <<<<<<<<<<<<<<<<<]
[2025-07-19 12:54:40,980 - INFO - main - >>>>>>>>>>>>>>>>>> Data Validation Stage started <<<<<<<<<<<<<<<<<]
[2025-07-19 12:54:40,981 - INFO - common - Successfully read YAML file at config/config.yaml]
[2025-07-19 12:54:40,981 - INFO - common - Successfully read YAML file at params.yaml]
[2025-07-19 12:54:40,981 - INFO - common - Successfully read YAML file at schema.yaml]
[2025-07-19 12:54:40,981 - INFO - common - Directory created at: artifacts]
[2025-07-19 12:54:40,981 - INFO - common - Directory created at: artifacts/data_validation]
[2025-07-19 12:54:40,984 - ERROR - data_validation - Exception occurred during data validation: 'DataValidationConfig' object has no attribute 'all_Schema']
Traceback (most recent call last):
  File "/Users/rahulsinghindata/AI-ML/ML_PROJECT_END_TO_END_17_07_2025/src/mlproject/components/data_validation.py", line 18, in validate_all_columns
    expected_cols = list(self.config.all_Schema["COLUMNS"].keys())
                         ^^^^^^^^^^^^^^^^^^^^^^
AttributeError: 'DataValidationConfig' object has no attribute 'all_Schema'. Did you mean: 'all_schema'?
[2025-07-19 12:54:40,984 - ERROR - main - 'DataValidationConfig' object has no attribute 'all_Schema']
Traceback (most recent call last):
  File "/Users/rahulsinghindata/AI-ML/ML_PROJECT_END_TO_END_17_07_2025/main.py", line 24, in <module>
    data_validation.main()
    ~~~~~~~~~~~~~~~~~~~~^^
  File "/Users/rahulsinghindata/AI-ML/ML_PROJECT_END_TO_END_17_07_2025/src/mlproject/pipeline/stage_02_data_validation.py", line 16, in main
    data_validation.validate_all_columns()
    ~~~~~~~~~~~~~~~~~~~~~~~~~~~~~~~~~~~~^^
  File "/Users/rahulsinghindata/AI-ML/ML_PROJECT_END_TO_END_17_07_2025/src/mlproject/components/data_validation.py", line 38, in validate_all_columns
    raise e
  File "/Users/rahulsinghindata/AI-ML/ML_PROJECT_END_TO_END_17_07_2025/src/mlproject/components/data_validation.py", line 18, in validate_all_columns
    expected_cols = list(self.config.all_Schema["COLUMNS"].keys())
                         ^^^^^^^^^^^^^^^^^^^^^^
AttributeError: 'DataValidationConfig' object has no attribute 'all_Schema'. Did you mean: 'all_schema'?
[2025-07-19 12:56:03,524 - INFO - main - Welcome to Custom Logging]
[2025-07-19 12:56:03,524 - INFO - main - >>>>>>>>>>>>>>>>>> Data Ingestion Stage started <<<<<<<<<<<<<<<<<]
[2025-07-19 12:56:03,524 - INFO - common - Successfully read YAML file at config/config.yaml]
[2025-07-19 12:56:03,525 - INFO - common - Successfully read YAML file at params.yaml]
[2025-07-19 12:56:03,526 - INFO - common - Successfully read YAML file at schema.yaml]
[2025-07-19 12:56:03,526 - INFO - common - Directory created at: artifacts]
[2025-07-19 12:56:03,526 - INFO - common - Directory created at: artifacts/data_ingestion]
[2025-07-19 12:56:03,526 - INFO - common - Directory created at: artifacts/data_ingestion]
[2025-07-19 12:56:03,526 - INFO - data_ingestion - File already exists at artifacts/data_ingestion/data.zip]
[2025-07-19 12:56:03,527 - INFO - data_ingestion - Extracted files to artifacts/data_ingestion]
[2025-07-19 12:56:03,527 - INFO - main - >>>>>>>>>>>>>>>>>> Data Ingestion Stage completed <<<<<<<<<<<<<<<<<]
[2025-07-19 12:56:03,527 - INFO - main - >>>>>>>>>>>>>>>>>> Data Validation Stage started <<<<<<<<<<<<<<<<<]
[2025-07-19 12:56:03,528 - INFO - common - Successfully read YAML file at config/config.yaml]
[2025-07-19 12:56:03,528 - INFO - common - Successfully read YAML file at params.yaml]
[2025-07-19 12:56:03,528 - INFO - common - Successfully read YAML file at schema.yaml]
[2025-07-19 12:56:03,528 - INFO - common - Directory created at: artifacts]
[2025-07-19 12:56:03,528 - INFO - common - Directory created at: artifacts/data_validation]
[2025-07-19 12:56:03,531 - ERROR - data_validation - Exception occurred during data validation: "'COLUMNS'"]
Traceback (most recent call last):
  File "box/box.py", line 594, in box.box.Box.__getitem__
KeyError: 'COLUMNS'

The above exception was the direct cause of the following exception:

Traceback (most recent call last):
  File "/Users/rahulsinghindata/AI-ML/ML_PROJECT_END_TO_END_17_07_2025/src/mlproject/components/data_validation.py", line 18, in validate_all_columns
    expected_cols = list(self.config.all_schema["COLUMNS"].keys())
                         ~~~~~~~~~~~~~~~~~~~~~~^^^^^^^^^^^
  File "box/box.py", line 621, in box.box.Box.__getitem__
box.exceptions.BoxKeyError: "'COLUMNS'"
[2025-07-19 12:56:03,531 - ERROR - main - "'COLUMNS'"]
Traceback (most recent call last):
  File "box/box.py", line 594, in box.box.Box.__getitem__
KeyError: 'COLUMNS'

The above exception was the direct cause of the following exception:

Traceback (most recent call last):
  File "/Users/rahulsinghindata/AI-ML/ML_PROJECT_END_TO_END_17_07_2025/main.py", line 24, in <module>
    data_validation.main()
    ~~~~~~~~~~~~~~~~~~~~^^
  File "/Users/rahulsinghindata/AI-ML/ML_PROJECT_END_TO_END_17_07_2025/src/mlproject/pipeline/stage_02_data_validation.py", line 16, in main
    data_validation.validate_all_columns()
    ~~~~~~~~~~~~~~~~~~~~~~~~~~~~~~~~~~~~^^
  File "/Users/rahulsinghindata/AI-ML/ML_PROJECT_END_TO_END_17_07_2025/src/mlproject/components/data_validation.py", line 38, in validate_all_columns
    raise e
  File "/Users/rahulsinghindata/AI-ML/ML_PROJECT_END_TO_END_17_07_2025/src/mlproject/components/data_validation.py", line 18, in validate_all_columns
    expected_cols = list(self.config.all_schema["COLUMNS"].keys())
                         ~~~~~~~~~~~~~~~~~~~~~~^^^^^^^^^^^
  File "box/box.py", line 621, in box.box.Box.__getitem__
box.exceptions.BoxKeyError: "'COLUMNS'"
[2025-07-19 13:04:48,892 - INFO - main - Welcome to Custom Logging]
[2025-07-19 13:04:48,893 - INFO - main - >>>>>>>>>>>>>>>>>> Data Ingestion Stage started <<<<<<<<<<<<<<<<<]
[2025-07-19 13:04:48,893 - INFO - common - Successfully read YAML file at config/config.yaml]
[2025-07-19 13:04:48,894 - INFO - common - Successfully read YAML file at params.yaml]
[2025-07-19 13:04:48,895 - INFO - common - Successfully read YAML file at schema.yaml]
[2025-07-19 13:04:48,895 - INFO - common - Directory created at: artifacts]
[2025-07-19 13:04:48,895 - INFO - common - Directory created at: artifacts/data_ingestion]
[2025-07-19 13:04:48,895 - INFO - common - Directory created at: artifacts/data_ingestion]
[2025-07-19 13:04:48,895 - INFO - data_ingestion - File already exists at artifacts/data_ingestion/data.zip]
[2025-07-19 13:04:48,896 - INFO - data_ingestion - Extracted files to artifacts/data_ingestion]
[2025-07-19 13:04:48,896 - INFO - main - >>>>>>>>>>>>>>>>>> Data Ingestion Stage completed <<<<<<<<<<<<<<<<<]
[2025-07-19 13:04:48,896 - INFO - main - >>>>>>>>>>>>>>>>>> Data Validation Stage started <<<<<<<<<<<<<<<<<]
[2025-07-19 13:04:48,896 - INFO - common - Successfully read YAML file at config/config.yaml]
[2025-07-19 13:04:48,896 - INFO - common - Successfully read YAML file at params.yaml]
[2025-07-19 13:04:48,897 - INFO - common - Successfully read YAML file at schema.yaml]
[2025-07-19 13:04:48,897 - INFO - common - Directory created at: artifacts]
[2025-07-19 13:04:48,897 - INFO - common - Directory created at: artifacts/data_validation]
[2025-07-19 13:04:48,899 - INFO - main - >>>>>>>>>>>>>>>>>> Data Validation Stage completed <<<<<<<<<<<<<<<<<]
